<?xml version="1.0"?>
<robot name="delivery_bot">

  <!-- MATERIALS -->
  <material name="black">
    <color rgba="0 0 0 1"/>
  </material>

  <material name="blue">
    <color rgba="0 0 1 1"/>
  </material>

  <material name="red">
    <color rgba="1 0 0 1"/>
  </material>

  <!-- BASE -->
  <link name="base_link">
    <visual>
    <origin xyz="0 0 0.08"/>
      <geometry>
        <box size="0.4 0.3 0.1"/>
      </geometry>
      <material name="blue"/>
    </visual>
<inertial>
  <origin xyz="0 0 -0.08"/>
  <mass value="3.0"/>
  <inertia ixx="0.05" iyy="0.05" izz="0.05"
           ixy="0.0" ixz="0.0" iyz="0.0"/>
</inertial>
<collision>
<origin xyz="0 0 0.08"/>
  <geometry>
    <box size="0.4 0.3 0.1"/>
  </geometry>
</collision>
  </link>
  
<gazebo reference="base_link">
  <material>Gazebo/Blue</material>
  <mu1>2.0</mu1>
  <mu2>2.0</mu2>
</gazebo>

<link name="caster_wheel">
  <visual>
    <geometry>
      <sphere radius="0.05"/>
    </geometry>
    <material name="black"/>
  </visual>

  <collision>
    <geometry>
      <sphere radius="0.05"/>
    </geometry>
  </collision>

  <inertial>
    <mass value="0.2"/>
    <inertia ixx="0.001" iyy="0.001" izz="0.001"
             ixy="0" ixz="0" iyz="0"/>
  </inertial>
</link>

<joint name="caster_joint" type="fixed">
  <parent link="base_link"/>
  <child link="caster_wheel"/>
  <origin xyz="-0.15 0 -0.06"/>
</joint>

<gazebo reference="caster_wheel">
  <mu1>0.0</mu1>
  <mu2>0.0</mu2>
</gazebo>

<!-- LEFT WHEEL -->
<link name="left_wheel">
  <visual>
   <origin xyz="0 0 0" rpy="1.5708 0 0"/>
    <geometry>
      <cylinder radius="0.07" length="0.08"/>
    </geometry>
    <material name="black"/>
  </visual>

  <collision>
   <origin xyz="0 0 0" rpy="1.5708 0 0"/>
    <geometry>
      <cylinder radius="0.07" length="0.08"/>
    </geometry>
    <surface>
  <friction>
    <ode>
      <mu>1.5</mu>
      <mu2>1.5</mu2>
    </ode>
  </friction>
    <contact>
    <ode>
      <kp>100000.0</kp>
      <kd>1.0</kd>
    </ode>
  </contact>
</surface>
  </collision>

  <inertial>
    <mass value="0.3"/>
    <inertia ixx="0.02" iyy="0.02" izz="0.02"
             ixy="0" ixz="0" iyz="0"/>
  </inertial>
</link>

<!-- RIGHT WHEEL -->
<link name="right_wheel">
  <visual>
   <origin xyz="0 0 0" rpy="1.5708 0 0"/>
    <geometry>
      <cylinder radius="0.07" length="0.08"/>
    </geometry>
    <material name="black"/>
  </visual>

  <collision>
   <origin xyz="0 0 0" rpy="1.5708 0 0"/>
    <geometry>
      <cylinder radius="0.07" length="0.08"/>
    </geometry>
    <surface>
  <friction>
    <ode>
      <mu>1.5</mu>
      <mu2>1.5</mu2>
    </ode>
  </friction>
    <contact>
    <ode>
      <kp>100000.0</kp>
      <kd>1.0</kd>
    </ode>
  </contact>
</surface>
</collision>

  <inertial>
    <mass value="0.3"/>
    <inertia ixx="0.02" iyy="0.02" izz="0.02"
             ixy="0" ixz="0" iyz="0"/>
  </inertial>
</link>
 <gazebo reference="left_wheel">
  <material>Gazebo/Black</material>
</gazebo>

<gazebo reference="right_wheel">
  <material>Gazebo/Black</material>
</gazebo>


  <!-- JOINTS -->

<!-- JOINTS -->
<joint name="left_wheel_joint" type="continuous">
  <parent link="base_link"/>
  <child link="left_wheel"/>
  <origin xyz="0 0.20 -0.03" rpy="0 0 0"/>
  <axis xyz="0 1 0"/>
  <dynamics damping="1.0" friction="0.2"/>
</joint>

<joint name="right_wheel_joint" type="continuous">
  <parent link="base_link"/>
  <child link="right_wheel"/>
  <origin xyz="0 -0.20 -0.03" rpy="0 0 0"/>
  <axis xyz="0 1 0"/>
  <dynamics damping="1.0" friction="0.2"/>
</joint>

<joint name="lidar_joint" type="fixed">
  <parent link="base_link"/>
  <child link="lidar_link"/>
  <origin xyz="0 0 0.1" rpy="0 0 0"/>
  
</joint>

<link name="base_footprint"/>

<joint name="base_joint" type="fixed">
  <parent link="base_footprint"/>
  <child link="base_link"/>
  <origin xyz="0 0 0.06" rpy="0 0 0"/>
</joint>

  <!-- LIDAR JOINT -->
 <link name="lidar_link">
  <visual>
    <geometry>
      <cylinder radius="0.05" length="0.05"/>
    </geometry>
    <material name="red"/>
  </visual>

  <collision>
    <geometry>
      <cylinder radius="0.05" length="0.05"/>
    </geometry>
  </collision>

  <inertial>
    <mass value="0.1"/>
    <inertia ixx="0.001" iyy="0.001" izz="0.001"
             ixy="0" ixz="0" iyz="0"/>
  </inertial>
</link>

<gazebo reference="lidar_link">
  <material>Gazebo/Red</material>

  <sensor name="lidar" type="ray">
    <update_rate>10</update_rate>

    <ray>
      <scan>
        <horizontal>
          <samples>360</samples>
          <min_angle>-3.14</min_angle>
          <max_angle>3.14</max_angle>
        </horizontal>
      </scan>

      <range>
        <min>0.1</min>
        <max>10.0</max>
      </range>
    </ray>

   
    <plugin name="gazebo_ros_laser" filename="libgazebo_ros_ray_sensor.so">
      <ros>
        <namespace>/</namespace>
        <remapping>~/out:=scan</remapping>
      </ros>
      <output_type>sensor_msgs/LaserScan</output_type>
      <frame_name>lidar_link</frame_name>
    </plugin>

  </sensor>
</gazebo>

<gazebo>
  <plugin name="diff_drive" filename="libgazebo_ros_diff_drive.so">

    <ros>
      <namespace>/</namespace>
    </ros>

    <update_rate>50</update_rate>

    <left_joint>left_wheel_joint</left_joint>
    <right_joint>right_wheel_joint</right_joint>

    <wheel_separation>0.4</wheel_separation>
    <wheel_diameter>0.14</wheel_diameter>

    <cmd_vel_topic>/cmd_vel</cmd_vel_topic>
    <odom_topic>/odom</odom_topic>

    <publish_odom>true</publish_odom>
    <publish_odom_tf>true</publish_odom_tf>
    
    <cmd_vel_timeout>0.3</cmd_vel_timeout>

    <max_linear_velocity>0.6</max_linear_velocity>
<max_angular_velocity>1.5</max_angular_velocity>

<max_linear_acceleration>0.8</max_linear_acceleration>
<max_angular_acceleration>1.5</max_angular_acceleration>
    
    <max_wheel_torque>10</max_wheel_torque>
    <max_wheel_acceleration>5</max_wheel_acceleration>
  </plugin>
</gazebo>

<gazebo>
  <plugin name="joint_state_publisher" filename="libgazebo_ros_joint_state_publisher.so">
    <update_rate>50</update_rate>

    <joint_name>left_wheel_joint</joint_name>
    <joint_name>right_wheel_joint</joint_name>
  </plugin>
</gazebo>


</robot>
